<?xml version="1.0" encoding="UTF-8"?>
<testng-results skipped="0" failed="2" ignored="0" total="2" passed="0">
  <reporter-output>
  </reporter-output>
  <suite name="Default suite" duration-ms="25625" started-at="2020-05-18T11:31:34Z" finished-at="2020-05-18T11:32:00Z">
    <groups>
    </groups>
    <test name="Default test" duration-ms="25625" started-at="2020-05-18T11:31:34Z" finished-at="2020-05-18T11:32:00Z">
      <class name="testngPack.FailureScreenshot">
        <test-method status="PASS" signature="beforeTest()[pri:0, instance:testngPack.FailureScreenshot@27efef64]" name="beforeTest" is-config="true" duration-ms="8484" started-at="2020-05-18T11:31:34Z" finished-at="2020-05-18T11:31:43Z">
          <reporter-output>
          </reporter-output>
        </test-method> <!-- beforeTest -->
        <test-method status="FAIL" signature="method1()[pri:0, instance:testngPack.FailureScreenshot@27efef64]" name="method1" duration-ms="5010" started-at="2020-05-18T11:31:43Z" finished-at="2020-05-18T11:31:48Z">
          <exception class="java.lang.AssertionError">
            <message>
              <![CDATA[expected [true] but found [false]]]>
            </message>
            <full-stacktrace>
              <![CDATA[java.lang.AssertionError: expected [true] but found [false]
at org.testng.Assert.fail(Assert.java:96)
at org.testng.Assert.failNotEquals(Assert.java:776)
at org.testng.Assert.assertTrue(Assert.java:44)
at org.testng.Assert.assertTrue(Assert.java:54)
at testngPack.FailureScreenshot.method1(FailureScreenshot.java:33)
at sun.reflect.NativeMethodAccessorImpl.invoke0(Native Method)
at sun.reflect.NativeMethodAccessorImpl.invoke(Unknown Source)
at sun.reflect.DelegatingMethodAccessorImpl.invoke(Unknown Source)
at java.lang.reflect.Method.invoke(Unknown Source)
at org.testng.internal.MethodInvocationHelper.invokeMethod(MethodInvocationHelper.java:124)
at org.testng.internal.Invoker.invokeMethod(Invoker.java:583)
at org.testng.internal.Invoker.invokeTestMethod(Invoker.java:719)
at org.testng.internal.Invoker.invokeTestMethods(Invoker.java:989)
at org.testng.internal.TestMethodWorker.invokeTestMethods(TestMethodWorker.java:125)
at org.testng.internal.TestMethodWorker.run(TestMethodWorker.java:109)
at org.testng.TestRunner.privateRun(TestRunner.java:648)
at org.testng.TestRunner.run(TestRunner.java:505)
at org.testng.SuiteRunner.runTest(SuiteRunner.java:455)
at org.testng.SuiteRunner.runSequentially(SuiteRunner.java:450)
at org.testng.SuiteRunner.privateRun(SuiteRunner.java:415)
at org.testng.SuiteRunner.run(SuiteRunner.java:364)
at org.testng.SuiteRunnerWorker.runSuite(SuiteRunnerWorker.java:52)
at org.testng.SuiteRunnerWorker.run(SuiteRunnerWorker.java:84)
at org.testng.TestNG.runSuitesSequentially(TestNG.java:1208)
at org.testng.TestNG.runSuitesLocally(TestNG.java:1137)
at org.testng.TestNG.runSuites(TestNG.java:1049)
at org.testng.TestNG.run(TestNG.java:1017)
at org.testng.remote.AbstractRemoteTestNG.run(AbstractRemoteTestNG.java:132)
at org.testng.remote.RemoteTestNG.initAndRun(RemoteTestNG.java:230)
at org.testng.remote.RemoteTestNG.main(RemoteTestNG.java:76)
]]>
            </full-stacktrace>
          </exception> <!-- java.lang.AssertionError -->
          <reporter-output>
          </reporter-output>
        </test-method> <!-- method1 -->
        <test-method status="PASS" signature="afterTest()[pri:0, instance:testngPack.FailureScreenshot@27efef64]" name="afterTest" is-config="true" duration-ms="657" started-at="2020-05-18T11:31:48Z" finished-at="2020-05-18T11:31:49Z">
          <reporter-output>
          </reporter-output>
        </test-method> <!-- afterTest -->
        <test-method status="PASS" signature="beforeTest()[pri:0, instance:testngPack.FailureScreenshot@27efef64]" name="beforeTest" is-config="true" duration-ms="5019" started-at="2020-05-18T11:31:49Z" finished-at="2020-05-18T11:31:54Z">
          <reporter-output>
          </reporter-output>
        </test-method> <!-- beforeTest -->
        <test-method status="FAIL" signature="method2()[pri:0, instance:testngPack.FailureScreenshot@27efef64]" name="method2" duration-ms="5007" started-at="2020-05-18T11:31:54Z" finished-at="2020-05-18T11:31:59Z">
          <exception class="java.lang.AssertionError">
            <message>
              <![CDATA[expected [true] but found [false]]]>
            </message>
            <full-stacktrace>
              <![CDATA[java.lang.AssertionError: expected [true] but found [false]
at org.testng.Assert.fail(Assert.java:96)
at org.testng.Assert.failNotEquals(Assert.java:776)
at org.testng.Assert.assertTrue(Assert.java:44)
at org.testng.Assert.assertTrue(Assert.java:54)
at testngPack.FailureScreenshot.method2(FailureScreenshot.java:40)
at sun.reflect.NativeMethodAccessorImpl.invoke0(Native Method)
at sun.reflect.NativeMethodAccessorImpl.invoke(Unknown Source)
at sun.reflect.DelegatingMethodAccessorImpl.invoke(Unknown Source)
at java.lang.reflect.Method.invoke(Unknown Source)
at org.testng.internal.MethodInvocationHelper.invokeMethod(MethodInvocationHelper.java:124)
at org.testng.internal.Invoker.invokeMethod(Invoker.java:583)
at org.testng.internal.Invoker.invokeTestMethod(Invoker.java:719)
at org.testng.internal.Invoker.invokeTestMethods(Invoker.java:989)
at org.testng.internal.TestMethodWorker.invokeTestMethods(TestMethodWorker.java:125)
at org.testng.internal.TestMethodWorker.run(TestMethodWorker.java:109)
at org.testng.TestRunner.privateRun(TestRunner.java:648)
at org.testng.TestRunner.run(TestRunner.java:505)
at org.testng.SuiteRunner.runTest(SuiteRunner.java:455)
at org.testng.SuiteRunner.runSequentially(SuiteRunner.java:450)
at org.testng.SuiteRunner.privateRun(SuiteRunner.java:415)
at org.testng.SuiteRunner.run(SuiteRunner.java:364)
at org.testng.SuiteRunnerWorker.runSuite(SuiteRunnerWorker.java:52)
at org.testng.SuiteRunnerWorker.run(SuiteRunnerWorker.java:84)
at org.testng.TestNG.runSuitesSequentially(TestNG.java:1208)
at org.testng.TestNG.runSuitesLocally(TestNG.java:1137)
at org.testng.TestNG.runSuites(TestNG.java:1049)
at org.testng.TestNG.run(TestNG.java:1017)
at org.testng.remote.AbstractRemoteTestNG.run(AbstractRemoteTestNG.java:132)
at org.testng.remote.RemoteTestNG.initAndRun(RemoteTestNG.java:230)
at org.testng.remote.RemoteTestNG.main(RemoteTestNG.java:76)
]]>
            </full-stacktrace>
          </exception> <!-- java.lang.AssertionError -->
          <reporter-output>
          </reporter-output>
        </test-method> <!-- method2 -->
        <test-method status="PASS" signature="afterTest()[pri:0, instance:testngPack.FailureScreenshot@27efef64]" name="afterTest" is-config="true" duration-ms="646" started-at="2020-05-18T11:31:59Z" finished-at="2020-05-18T11:32:00Z">
          <reporter-output>
          </reporter-output>
        </test-method> <!-- afterTest -->
      </class> <!-- testngPack.FailureScreenshot -->
    </test> <!-- Default test -->
  </suite> <!-- Default suite -->
</testng-results>
